Workbook

Sheet Relatorio_Carga_Maquina1
A1: Grupo 3
A2: Recurso | B2: Cod. | C2: Descrição | D2: Período | E2: Car. Total | F2: Car. Disp. | G2: Car. Prog. | H2: % Carga | I2: Car. Terc. | J2: Car. Setup | K2: % Setup | L2: horas extras
A3: 1 | B3: TC_1 | C3: TEAR CIRCULAR 1
D4: 13 | E4: 84 | F4: 84 | G4: 83.95 | H4: 99.94 | I4: 0 | J4: 0.25 | K4: 0.3
D5: 14 | E5: 84 | F5: 84 | G5: 83.95 | H5: 99.94 | I5: 0 | J5: 0.25 | K5: 0.3
D6: 15 | E6: 84 | F6: 84 | G6: 83.95 | H6: 99.94 | I6: 0 | J6: 0.25 | K6: 0.3
D7: 16 | E7: 84 | F7: 84 | G7: 83.95 | H7: 99.94 | I7: 0 | J7: 0.25 | K7: 0.3
D8: 17 | E8: 84 | F8: 84 | G8: 83.95 | H8: 99.94 | I8: 0 | J8: 0.25 | K8: 0.3
D9: 18 | E9: 84 | F9: 84 | G9: 83.95 | H9: 99.94 | I9: 0 | J9: 0.25 | K9: 0.3
D10: 19 | E10: 84 | F10: 84 | G10: 83.95 | H10: 99.94 | I10: 0 | J10: 0.25 | K10: 0.3
D11: 20 | E11: 84 | F11: 84 | G11: 83.95 | H11: 99.94 | I11: 0 | J11: 0.25 | K11: 0.3
D12: 21 | E12: 84 | F12: 84 | G12: 83.95 | H12: 99.94 | I12: 0 | J12: 0.25 | K12: 0.3
D13: 22 | E13: 84 | F13: 84 | G13: 83.95 | H13: 99.94 | I13: 0 | J13: 0.25 | K13: 0.3
D14: 23 | E14: 84 | F14: 84 | G14: 83.95 | H14: 99.94 | I14: 0 | J14: 0.25 | K14: 0.3
D15: 24 | E15: 84 | F15: 84 | G15: 83.95 | H15: 99.94 | I15: 0 | J15: 0.25 | K15: 0.3
A16: 2 | B16: TC_2 | C16: TEAR CIRCULAR 2
D17: 13 | E17: 84 | F17: 84 | G17: 81.25 | H17: 96.73 | I17: 0 | J17: 0.25 | K17: 0.3
D18: 14 | E18: 84 | F18: 84 | G18: 81.25 | H18: 96.73 | I18: 0 | J18: 0.25 | K18: 0.3
D19: 15 | E19: 84 | F19: 84 | G19: 81.25 | H19: 96.73 | I19: 0 | J19: 0.25 | K19: 0.3
D20: 16 | E20: 84 | F20: 84 | G20: 81.25 | H20: 96.73 | I20: 0 | J20: 0.25 | K20: 0.3
D21: 17 | E21: 84 | F21: 84 | G21: 81.25 | H21: 96.73 | I21: 0 | J21: 0.25 | K21: 0.3
D22: 18 | E22: 84 | F22: 84 | G22: 81.25 | H22: 96.73 | I22: 0 | J22: 0.25 | K22: 0.3
D23: 19 | E23: 84 | F23: 84 | G23: 81.25 | H23: 96.73 | I23: 0 | J23: 0.25 | K23: 0.3
D24: 20 | E24: 84 | F24: 84 | G24: 81.25 | H24: 96.73 | I24: 0 | J24: 0.25 | K24: 0.3
D25: 21 | E25: 84 | F25: 84 | G25: 81.25 | H25: 96.73 | I25: 0 | J25: 0.25 | K25: 0.3
D26: 22 | E26: 84 | F26: 84 | G26: 81.25 | H26: 96.73 | I26: 0 | J26: 0.25 | K26: 0.3
D27: 23 | E27: 84 | F27: 84 | G27: 81.25 | H27: 96.73 | I27: 0 | J27: 0.25 | K27: 0.3
D28: 24 | E28: 84 | F28: 84 | G28: 81.25 | H28: 96.73 | I28: 0 | J28: 0.25 | K28: 0.3
A29: 3 | B29: TC_3 | C29: TEAR CIRCULAR 3
D30: 13 | E30: 84 | F30: 84 | G30: 82.75 | H30: 98.51 | I30: 0 | J30: 0.25 | K30: 0.3
D31: 14 | E31: 84 | F31: 84 | G31: 82.75 | H31: 98.51 | I31: 0 | J31: 0.25 | K31: 0.3
D32: 15 | E32: 84 | F32: 84 | G32: 82.75 | H32: 98.51 | I32: 0 | J32: 0.25 | K32: 0.3
D33: 16 | E33: 84 | F33: 84 | G33: 82.75 | H33: 98.51 | I33: 0 | J33: 0.25 | K33: 0.3
D34: 17 | E34: 84 | F34: 84 | G34: 82.75 | H34: 98.51 | I34: 0 | J34: 0.25 | K34: 0.3
D35: 18 | E35: 84 | F35: 84 | G35: 82.75 | H35: 98.51 | I35: 0 | J35: 0.25 | K35: 0.3
D36: 19 | E36: 84 | F36: 84 | G36: 82.75 | H36: 98.51 | I36: 0 | J36: 0.25 | K36: 0.3
D37: 20 | E37: 84 | F37: 84 | G37: 82.75 | H37: 98.51 | I37: 0 | J37: 0.25 | K37: 0.3
D38: 21 | E38: 84 | F38: 84 | G38: 82.75 | H38: 98.51 | I38: 0 | J38: 0.25 | K38: 0.3
D39: 22 | E39: 84 | F39: 84 | G39: 82.75 | H39: 98.51 | I39: 0 | J39: 0.25 | K39: 0.3
D40: 23 | E40: 84 | F40: 84 | G40: 82.75 | H40: 98.51 | I40: 0 | J40: 0.25 | K40: 0.3
...

Sheet Gráfico 2 - Carregamento
A1: Recurso | B1: % Carga média
A2: Jet 1 | B2: =AVERAGE(Relatorio_Carga_Maquina1!H69:H80) -> 86.923333
A3: Jet 2 | B3: =AVERAGE(Relatorio_Carga_Maquina1!H82:H93) -> 85.7425
A4: Jet 3 | B4: =AVERAGE(Relatorio_Carga_Maquina1!H95:H106) -> 87.1725
A5: Rama | B5: =AVERAGE(Relatorio_Carga_Maquina1!H108:H119) -> 65.158333

Sheet Gráfico 6 - Horas extra e terc
A1: Recurso | B1: Horas terceirizadas | C1: Horas extras
A2: Jet 1 | B2: =SUM(Relatorio_Carga_Maquina1!I69:I80) -> 0
A3: Jet 2 | B3: =SUM(Relatorio_Carga_Maquina1!I82:I93) -> 28 | C3: 0
A4: Jet 3 | B4: =SUM(Relatorio_Carga_Maquina1!I95:I106) -> 56 | C4: 0
A5: Rama | B5: =SUM(Relatorio_Carga_Maquina1!I108:I119) -> 0 | C5: 84
